Workbook

Sheet Summary
C2: Total Acres | D2: =SUM(D5+K5+R5) -> 5228.3766 | E2: Total Acres Picked | G2: =SUM(D6+K6+R6) -> 1838.7201 | H2: =G2/D2 -> 0.35168088 | I2: Total Acres In Progress | K2: =SUM(D7+K7+R7) -> 122.66 | L2: =K2/D2 -> 0.023460437 | O2: Total Acres Pending | Q2: =D8+K8+R8 -> 3053.2465 | R2: =Q2/D2 -> 0.58397601
C5: Clements Acres | D5: =SUM(C13:C67) -> 1992.3565 | J5: Delta Acres | K5: =SUM(J13:J65) -> 1323.11 | Q5: Lodi Acres | R5: =SUM(Q13:Q87) -> 1912.9101
C6: Picked | D6: =SUM(E13:E75) -> 384.98 | E6: =D6/(D5) -> 0.19322847 | J6: Picked | K6: =SUM(L13:L72) -> 884.5 | L6: =K6/(K5) -> 0.66850073 | Q6: Picked | R6: =SUM(S13:S93) -> 569.24009 | S6: =R6/(R5) -> 0.29757807
C7: In Progress | D7: =D19+D42+D67 -> 65.83 | E7: =D7/(D5) -> 0.033041275 | J7: In Progress | K7: =K33+K54 -> 9.28 | L7: =K7/(K5) -> 0.0070137781 | Q7: In Progress | R7: =R21+R49+R50+R62 -> 47.55 | S7: =R7/(R5) -> 0.024857415
C8: Pending | D8: =SUM(D13:D18,D20:D26,D29:D30,D35:D37,D32:D33,D39:D41,D43:D52,D54:D57,D59,D61:D66) -> 1536.5465 | E8: =D8/(D5) -> 0.77122067 | J8: Pending | K8: =SUM(K34:K38,K42:K43,K56,K61) -> 224.53 | L8: =K8/(K5) -> 0.16969866 | Q8: Pending | R8: =R5-(R6+R7+R9) -> 1292.17 | S8: =R8/(R5) -> 0.6754996
C9: No/Maybe Pick | D9: 5 | E9: =D9/D5 -> 0.002509591 | J9: No/Maybe Pick | K9: =K19+K20+K23+K24+K25+K26+K27+K28+K29+K47+K48+K50+K51+K58 -> 202.68 | L9: =K9/K5 -> 0.15318454 | Q9: No/Maybe Pick | R9: 3.95 | S9: =R9/R5 -> 0.0020649167
B11: CLEMENTS | I11: DELTA | P11: LODI
B12: CODE | C12: ACRES | D12: AC. LEFT | E12: FINISHED | F12: TONS | G12: TPA | I12: CODE | J12: ACRES | K12: AC. LEFT | L12: FINISHED | M12: TONS | N12: TPA | P12: CODE | Q12: ACRES | R12: AC. LEFT | S12: FINISHED | T12: TONS | U12: TPA
B13: 98OK01CS | C13: 22.945684 | D13: =C13 -> 22.945684 | E13: =C13-D13 -> 0 | I13: DVDU02SB | J13: 39.42 | K13: 0 | L13: =J13-K13 -> 39.42 | P13: ARDA01CS | Q13: 36.81 | R13: =Q13 -> 36.81 | S13: =Q13-R13 -> 0 | U13: =IFERROR(T13/S13,"")
B14: 98OK02CS | C14: 15.91072 | D14: =C14 -> 15.91072 | E14: =C14-D14 -> 0 | I14: DVDU05CH | J14: 42.04 | K14: 0 | L14: =J14-K14 -> 42.04 | P14: BAPE01CH | Q14: 42.120091 | R14: 0 | S14: =Q14-R14 -> 42.120091 | U14: =IFERROR(T14/S14,"") -> 0
B15: 98OK03MA | C15: 19.051904 | D15: =C15 -> 19.051904 | E15: =C15-D15 -> 0 | I15: DVDU07MC | J15: 28.51 | K15: 0.5 | L15: =J15-K15 -> 28.01 | P15: BEBU01ME | Q15: 46.96 | R15: 0 | S15: =Q15-R15 -> 46.96 | U15: =IFERROR(T15/S15,"") -> 0
B16: 98OK04CS | C16: 26.525629 | D16: =C16 -> 26.525629 | E16: =C16-D16 -> 0 | I16: DVDU1CSB | J16: 45.21 | K16: 0 | L16: =J16-K16 -> 45.21 | P16: DBAI02SA | Q16: 10.03 | R16: =Q16 -> 10.03 | S16: =Q16-R16 -> 0 | U16: =IFERROR(T16/S16,"")
B17: 98OK05CS | C17: 20.2326 | D17: =C17 -> 20.2326 | E17: =C17-D17 -> 0 | I17: DVMA01PN | J17: 46.69 | K17: 0 | L17: =J17-K17 -> 46.69 | P17: DBAI03ZN | Q17: 9.27 | R17: 0 | S17: =Q17-R17 -> 9.27
B18: 98OK06CS | C18: 24.5 | D18: =C18 -> 24.5 | E18: =C18-D18 -> 0 | I18: DVMA02PG | J18: 102.93 | K18: 0 | L18: =J18-K18 -> 102.93 | P18: DBAI04CS | Q18: 9.27 | R18: =Q18 -> 9.27 | S18: =Q18-R18 -> 0 | U18: =IFERROR(T18/S18,"")
B19: 98OK07ME | C19: 37.6 | D19: 24.62 | E19: =C19-D19 -> 12.98 | I19: FFRY01PN | J19: 38.21 | K19: 0.33 | L19: =J19-K19 -> 37.88 | P19: DBDA05CH | Q19: 10.07 | R19: 10.07 | S19: 0 | U19: =IFERROR(T19/S19,"")
B20: 98OK08PS | C20: 24.5 | D20: =C20 -> 24.5 | E20: =C20-D20 -> 0 | I20: FFRY02PN | J20: 15.18 | K20: =J20 -> 15.18 | L20: =J20-K20 -> 0 | P20: DFDA04ZN | Q20: 8.07 | R20: 0 | S20: =Q20-R20 -> 8.07 | U20: =IFERROR(T20/S20,"") -> 0
B21: 98OK09CS | C21: 39.2 | D21: =C21 -> 39.2 | E21: =C21-D21 -> 0 | I21: FFRY04CH | J21: 15.95 | K21: 0.71 | L21: =J21-K21 -> 15.24 | P21: DFDA07ND | Q21: 6.72 | R21: 0.29 | S21: =Q21-R21 -> 6.43 | U21: =IFERROR(T21/S21,"") -> 0
B22: 98OK10ZN | C22: 18.8 | D22: =C22 -> 18.8 | E22: =C22-D22 -> 0 | I22: FFRY05CH | J22: 24.82 | K22: 0.91 | L22: =J22-K22 -> 23.91 | P22: FDJA01TO | Q22: 20.25 | R22: =Q22 -> 20.25 | S22: =Q22-R22 -> 0 | U22: =IFERROR(T22/S22,"")
B23: 98OK11CF | C23: 21 | D23: =C23 -> 21 | E23: =C23-D23 -> 0 | I23: FFRY09PN | J23: 4.53 | K23: =J23 -> 4.53 | L23: =J23-K23 -> 0 | P23: FDJA02TE | Q23: 20.26 | R23: =Q23 -> 20.26 | S23: =Q23-R23 -> 0 | U23: =IFERROR(T23/S23,"")
B24: BAVC01ZN | C24: 17.14 | D24: =C24 -> 17.14 | E24: =C24-D24 -> 0 | I24: FFRY10PN | J24: 9.48 | K24: =J24 -> 9.48 | L24: =J24-K24 -> 0 | P24: FDJA03MA | Q24: 36.25 | R24: =Q24 -> 36.25 | S24: =Q24-R24 -> 0 | U24: =IFERROR(T24/S24,"")
B25: BAVC02PR | C25: 11.79 | D25: =C25 -> 11.79 | E25: =C25-D25 -> 0 | I25: FFRY15CB | J25: 41.01 | K25: =J25 -> 41.01 | L25: =J25-K25 -> 0 | P25: FDJA04ME | Q25: 41.1 | R25: =Q25 -> 41.1 | S25: =Q25-R25 -> 0 | U25: =IFERROR(T25/S25,"")
B26: BHCH01CS | C26: 45.32 | D26: =C26 -> 45.32 | E26: =C26-D26 -> 0 | I26: FFRY3BXX | J26: 19.96 | K26: =J26 -> 19.96 | L26: =J26-K26 -> 0 | P26: FDJA05ME | Q26: 18.39 | R26: =Q26 -> 18.39 | S26: =Q26-R26 -> 0 | U26: =IFERROR(T26/S26,"")
B27: BSHMOHCS | C27: 5 | D27: =C27 -> 5 | E27: =C27-D27 -> 0 | I27: FFRY99PN | J27: 18.11 | K27: =J27 -> 18.11 | L27: =J27-K27 -> 0 | P27: FRDU01ME | Q27: 3.73 | R27: =Q27 -> 3.73 | S27: =Q27-R27 -> 0 | U27: =IFERROR(T27/S27,"")
B28: CL3A02SB | C28: 50.74 | D28: 0 | E28: =C28-D28 -> 50.74 | I28: MFRN00PN | J28: 5 | K28: =J28 -> 5 | L28: =J28-K28 -> 0 | P28: HEBO01CS | Q28: 17.14 | R28: =Q28 -> 17.14 | S28: =Q28-R28 -> 0 | U28: =IFERROR(T28/S28,"")
B29: CLAT05CS | C29: 34.92 | D29: =C29 -> 34.92 | E29: =C29-D29 -> 0 | I29: MFRN02PN | J29: 45.71 | K29: 23.75 | L29: =J29-K29 -> 21.96 | P29: HIHV04CS | Q29: 44.56 | R29: =Q29 -> 44.56 | S29: =Q29-R29 -> 0 | U29: =IFERROR(T29/S29,"")
B30: CLBC00VD | C30: 7.1 | D30: =C30 -> 7.1 | E30: =C30-D30 -> 0 | I30: MFRN03PG | J30: 45.11 | K30: 0 | L30: =J30-K30 -> 45.11 | P30: HIHV05PS | Q30: 57.07 | R30: =Q30 -> 57.07 | S30: =Q30-R30 -> 0 | U30: =IFERROR(T30/S30,"")
B31: CLBC01PG | C31: =39.34 -> 39.34 | D31: 0 | E31: =C31 -> 39.34 | F31: 264 | G31: =F31/C31 -> 6.710727 | I31: MJMJ02PG | J31: 66.53 | K31: 0 | L31: =J31-K31 -> 66.53 | P31: IWHM01CS | Q31: 3.95 | R31: =Q31 -> 3.95 | S31: =Q31-R31 -> 0 | U31: =IFERROR(T31/S31,"")
B32: CLBC02CH | C32: 59.54 | D32: =C32 -> 59.54 | E32: =C32-D32 -> 0 | I32: MJMJ03CB | J32: 19.38 | K32: 0 | L32: =J32-K32 -> 19.38 | P32: JONR01CH | Q32: 37.82 | R32: 0 | S32: =Q32-R32 -> 37.82 | U32: =IFERROR(T32/S32,"") -> 0
B33: CLLA01ME | C33: 72.66 | D33: =C33 -> 72.66 | E33: =C33-D33 -> 0 | I33: MJMJ04CB | J33: 36.77 | K33: 6.78 | L33: =J33-K33 -> 29.99 | P33: JONR02SB | Q33: 7.06 | R33: 0 | S33: =Q33-R33 -> 7.06 | U33: =IFERROR(T33/S33,"") -> 0
B34: CLMN01SY | C34: 60.52 | D34: 0 | E34: =C34-D34 -> 60.52 | I34: ONMI01CS | J34: 36.13 | K34: =J34 -> 36.13 | L34: =J34-K34 -> 0 | P34: JONR03GV | Q34: 4.51 | R34: 4.51 | S34: 0 | U34: =IFERROR(T34/S34,"")
B35: CLMN03PS | C35: 4.97 | D35: =C35 -> 4.97 | E35: =C35-D35 -> 0 | I35: ONMI02CS | J35: 41.4 | K35: =J35 -> 41.4 | L35: =J35-K35 -> 0 | P35: LAPR02CH | Q35: 34.2 | R35: =Q35 -> 34.2 | S35: =Q35-R35 -> 0 | U35: =IFERROR(T35/S35,"")
B36: CLMN04PS | C36: 12.29 | D36: =C36 -> 12.29 | E36: =C36-D36 -> 0 | I36: ONMI04CS | J36: 30.18 | K36: =J36 -> 30.18 | L36: =J36-K36 -> 0 | P36: LAPR03ME | Q36: 34.06 | R36: =Q36 -> 34.06 | S36: =Q36-R36 -> 0 | U36: =IFERROR(T36/S36,"")
B37: CLMN05PS | C37: 16.22 | D37: =C37 -> 16.22 | E37: =C37-D37 -> 0 | I37: ONMI05CS | J37: 32.99 | K37: =J37 -> 32.99 | L37: =J37-K37 -> 0 | P37: LAPR04PS | Q37: 43.76 | R37: =Q37 -> 43.76 | S37: =Q37-R37 -> 0 | U37: =IFERROR(T37/S37,"")
B38: CLMO01BA | C38: 34.41 | D38: 0 | E38: =C38-D38 -> 34.41 | I38: ONMI06CS | J38: 30.71 | K38: =J38 -> 30.71 | L38: =J38-K38 -> 0 | P38: LAPR05CS | Q38: 43.1 | R38: =Q38 -> 43.1 | S38: =Q38-R38 -> 0 | U38: =IFERROR(T38/S38,"")
B39: CLNR01CS | C39: 59.72 | D39: =C39 -> 59.72 | E39: =C39-D39 -> 0 | I39: ONMI07ME | J39: 38.76 | K39: 0 | L39: =J39-K39 -> 38.76 | P39: LF1001CS | Q39: 49.01 | R39: =Q39 -> 49.01 | S39: =Q39-R39 -> 0 | U39: =IFERROR(T39/S39,"")
B40: CLOK02CS | C40: 104.19 | D40: =C40 -> 104.19 | E40: =C40-D40 -> 0 | I40: ONMI08ME | J40: 38.34 | K40: 0 | L40: =J40-K40 -> 38.34 | P40: LF1002PS | Q40: 49.52 | R40: =Q40 -> 49.52 | S40: =Q40-R40 -> 0 | U40: =IFERROR(T40/S40,"")
B41: CLOK1AME | C41: 50.38 | D41: =C41 -> 50.38 | E41: =C41-D41 -> 0 | I41: ONMI09CH | J41: 39.13 | K41: 0 | L41: =J41-K41 -> 39.13 | P41: LF3801CS | Q41: 48.52 | R41: =Q41 -> 48.52 | S41: =Q41-R41 -> 0 | U41: =IFERROR(T41/S41,"")
B42: CLPC02BA | C42: 28.07 | D42: 11.58 | E42: =C42-D42 -> 16.49 | I42: ONMI3ACS | J42: 8.77 | K42: =J42 -> 8.77 | L42: =J42-K42 -> 0 | P42: LF8001TD | Q42: 24.87 | R42: =Q42 -> 24.87 | S42: =Q42-R42 -> 0 | U42: =IFERROR(T42/S42,"")
B43: CLPC07CS | C43: 86.1 | D43: =C43 -> 86.1 | E43: =C43-D43 -> 0 | I43: ONMI3BCS | J43: 25.73 | K43: =J43 -> 25.73 | L43: =J43-K43 -> 0 | P43: LF8004CH | Q43: 18.48 | R43: 0 | S43: =Q43-R43 -> 18.48
B44: CLPC3BME | C44: 43.28 | D44: =C44 -> 43.28 | E44: =C44-D44 -> 0 | I44: PRHZ01CH | J44: 12.58 | K44: 0 | L44: =J44-K44 -> 12.58 | P44: LFBE01CS | Q44: 58.08 | R44: =Q44 -> 58.08 | S44: =Q44-R44 -> 0 | U44: =IFERROR(T44/S44,"")
...

Sheet Row Counts
A1: REMINDER: FILTER ONLY - DO NOT SORT!
A2: DATE | B2: BLOCK | C2: VINE SPACING | D2: TOTAL VINES | E2: VINES PICKED | F2: VINES LEFT | G2: TOTAL ACRES | H2: ACRES PICKED | I2: ACRES LEFT | J2: ACRES PICKED SINCE LAST COUNT | K2: LOADS | L2: WINERY | M2: TONS PICKED TODAY | N2: TPA | O2: LOADS TO FINISH | P2: ROW COUNT REPORTED BY | Q2: ROWS | R2: NOTES
A3: 46218 | B3: LF8004CH | C3: {=IF(B3="","",_xlfn._xlws.FILTER('Source List'!I$2:I$268,'Source List'!G$2:G$268='Row Counts'!B3," "))} -> 622 | D3: {=IF(B3="","",_xlfn._xlws.FILTER('Source List'!J$2:J$268,'Source List'!G$2:G$268='Row Counts'!B3," "))} -> 11433 | E3: 5585 | F3: =Table1[[#This Row],[TOTAL VINES]]-Table1[[#This Row],[VINES PICKED]] -> 5848 | G3: =IFERROR(D3/C3,0) -> 18.381029 | H3: =IFERROR(E3/C3,0) -> 8.9790997 | I3: =Table1[[#This Row],[TOTAL ACRES]]-Table1[[#This Row],[ACRES PICKED]] -> 9.4019293 | J3: =Table1[[#This Row],[ACRES PICKED]] -> 8.9790997 | K3: 2.5 | L3: LTW | M3: 53.55 | N3: =IFERROR(M3/J3,0) -> 5.9638496 | O3: =IFERROR((N3*I3)/23,"") -> 2.4378997 | P3: Luis | Q3: Picked: 24-45 (Rosa FC)
A4: 46224 | B4: LFEX01SA | C4: {=IF(B4="","",_xlfn._xlws.FILTER('Source List'!I$2:I$268,'Source List'!G$2:G$268='Row Counts'!B4," "))} -> 605 | D4: {=IF(B4="","",_xlfn._xlws.FILTER('Source List'!J$2:J$268,'Source List'!G$2:G$268='Row Counts'!B4," "))} -> 10120 | E4: 2356 | F4: =Table1[[#This Row],[TOTAL VINES]]-Table1[[#This Row],[VINES PICKED]] -> 7764 | G4: =IFERROR(D4/C4,0) -> 16.727273 | H4: =IFERROR(E4/C4,0) -> 3.8942149 | I4: =Table1[[#This Row],[TOTAL ACRES]]-Table1[[#This Row],[ACRES PICKED]] -> 12.833058 | J4: =Table1[[#This Row],[ACRES PICKED]] -> 3.8942149 | K4: 1 | L4: LTW | M4: 24.43 | N4: =IFERROR(M4/J4,0) -> 6.2734083 | O4: =IFERROR((N4*I4)/23,"") -> 3.5003049 | P4: Luis | Q4: Picked: 8-23,25,27,39(1/2)
A5: 46224 | B5: DBAI03ZN | C5: {=IF(B5="","",_xlfn._xlws.FILTER('Source List'!I$2:I$268,'Source List'!G$2:G$268='Row Counts'!B5," "))} -> 622 | D5: {=IF(B5="","",_xlfn._xlws.FILTER('Source List'!J$2:J$268,'Source List'!G$2:G$268='Row Counts'!B5," "))} -> 5633 | E5: =2604+25 -> 2629 | F5: =Table1[[#This Row],[TOTAL VINES]]-Table1[[#This Row],[VINES PICKED]] -> 3004 | G5: =IFERROR(D5/C5,0) -> 9.0562701 | H5: =IFERROR(E5/C5,0) -> 4.2266881 | I5: =Table1[[#This Row],[TOTAL ACRES]]-Table1[[#This Row],[ACRES PICKED]] -> 4.829582 | J5: =Table1[[#This Row],[ACRES PICKED]] -> 4.2266881 | K5: 1 | L5: LTW | M5: 24.37 | N5: =IFERROR(M5/J5,0) -> 5.7657436 | O5: =IFERROR((N5*I5)/23,"") -> 1.2107014 | P5: Luis | Q5: Picked: 6-41,43,45,47(25vines)
A6: 46226 | B6: CLBC01PG | C6: {=IF(B6="","",_xlfn._xlws.FILTER('Source List'!I$2:I$268,'Source List'!G$2:G$268='Row Counts'!B6," "))} -> 681 | D6: {=IF(B6="","",_xlfn._xlws.FILTER('Source List'!J$2:J$268,'Source List'!G$2:G$268='Row Counts'!B6," "))} -> 26421 | E6: 13699 | F6: =Table1[[#This Row],[TOTAL VINES]]-Table1[[#This Row],[VINES PICKED]] -> 12722 | G6: =IFERROR(D6/C6,0) -> 38.797357 | H6: =IFERROR(E6/C6,0) -> 20.116006 | I6: =Table1[[#This Row],[TOTAL ACRES]]-Table1[[#This Row],[ACRES PICKED]] -> 18.681351 | J6: =Table1[[#This Row],[ACRES PICKED]] -> 20.116006 | K6: 6 | L6: Oneill | M6: 142.24 | N6: =IFERROR(M6/J6,0) -> 7.0709862 | O6: =IFERROR((N6*I6)/23,"") -> 5.7432859 | P6: Luis | Q6: Picked: 1-34,36-48,50,52,54,56,65,67,69-72-74,76, Row 56 is 3/4 picked, Row 73 is 1/2 picked. We estimated for unknowns
A7: 46227 | B7: CLBC01PG | C7: {=IF(B7="","",_xlfn._xlws.FILTER('Source List'!I$2:I$268,'Source List'!G$2:G$268='Row Counts'!B7," "))} -> 681 | D7: {=IF(B7="","",_xlfn._xlws.FILTER('Source List'!J$2:J$268,'Source List'!G$2:G$268='Row Counts'!B7," "))} -> 26421 | E7: =IFERROR(Table1[[#This Row],[TOTAL VINES]]-Table1[[#This Row],[VINES LEFT]],"") -> 26421 | F7: =Table1[[#This Row],[TOTAL VINES]]-Table1[[#This Row],[VINES PICKED]] -> 0 | G7: =IFERROR(D7/C7,0) -> 38.797357 | H7: =IFERROR(E7/C7,0) -> 38.797357 | I7: =Table1[[#This Row],[TOTAL ACRES]]-Table1[[#This Row],[ACRES PICKED]] -> 0 | J7: =I6 -> 18.681351 | K7: 5.25 | L7: Oneill | M7: 122.51 | N7: =IFERROR(M7/J7,0) -> 6.5578769 | O7: =IFERROR((N7*I7)/23,"") -> 0 | P7: Luis | Q7: FC
A8: 46230 | B8: DVDU1CSB | C8: {=IF(B8="","",_xlfn._xlws.FILTER('Source List'!I$2:I$268,'Source List'!G$2:G$268='Row Counts'!B8," "))} -> 726 | D8: {=IF(B8="","",_xlfn._xlws.FILTER('Source List'!J$2:J$268,'Source List'!G$2:G$268='Row Counts'!B8," "))} -> 32514 | E8: =IFERROR(Table1[[#This Row],[TOTAL VINES]]-Table1[[#This Row],[VINES LEFT]],"") -> 13022 | F8: =18893+199+300+100 -> 19492 | G8: =IFERROR(D8/C8,0) -> 44.785124 | H8: =IFERROR(E8/C8,0) -> 17.936639 | I8: =Table1[[#This Row],[TOTAL ACRES]]-Table1[[#This Row],[ACRES PICKED]] -> 26.848485 | J8: =Table1[[#This Row],[ACRES PICKED]] -> 17.936639 | K8: 6 | L8: Gallo | M8: 134.45 | N8: =IFERROR(M8/J8,0) -> 7.4958301 | O8: =IFERROR((N8*I8)/23,"") -> 8.7500731 | P8: Luis | Q8: Left to pick: 9,13,15,24,26,28-40,48,50,52-81, row 24 1/2 picked, row 15 1/4 picked, row 48 3/4 picked
A9: 46230 | B9: LFEX01SA | C9: {=IF(B9="","",_xlfn._xlws.FILTER('Source List'!I$2:I$268,'Source List'!G$2:G$268='Row Counts'!B9," "))} -> 605 | D9: {=IF(B9="","",_xlfn._xlws.FILTER('Source List'!J$2:J$268,'Source List'!G$2:G$268='Row Counts'!B9," "))} -> 10120 | E9: 6532 | F9: =Table1[[#This Row],[TOTAL VINES]]-Table1[[#This Row],[VINES PICKED]] -> 3588 | G9: =IFERROR(D9/C9,0) -> 16.727273 | H9: =IFERROR(E9/C9,0) -> 10.796694 | I9: =Table1[[#This Row],[TOTAL ACRES]]-Table1[[#This Row],[ACRES PICKED]] -> 5.9305785 | J9: =Table1[[#This Row],[ACRES PICKED]] -> 10.796694 | K9: 2 | L9: LTW | M9: 51.27 | N9: =IFERROR(M9/J9,0) -> 4.7486758 | O9: =IFERROR((N9*I9)/23,"") -> 1.2244519 | P9: Kyle | Q9: Picked rows: 8-55, 56(1/2), 57, 59, 61(1/2)
A10: 46230 | B10: MUMU02PG | C10: {=IF(B10="","",_xlfn._xlws.FILTER('Source List'!I$2:I$268,'Source List'!G$2:G$268='Row Counts'!B10," "))} -> 681 | D10: {=IF(B10="","",_xlfn._xlws.FILTER('Source List'!J$2:J$268,'Source List'!G$2:G$268='Row Counts'!B10," "))} -> 14141 | E10: =IFERROR(Table1[[#This Row],[TOTAL VINES]]-Table1[[#This Row],[VINES LEFT]],"") -> 8916 | F10: 5225 | G10: =IFERROR(D10/C10,0) -> 20.765051 | H10: =IFERROR(E10/C10,0) -> 13.092511 | I10: =Table1[[#This Row],[TOTAL ACRES]]-Table1[[#This Row],[ACRES PICKED]] -> 7.6725404 | J10: =Table1[[#This Row],[ACRES PICKED]] -> 13.092511 | K10: 3 | L10: Fetzer | M10: 69.71 | N10: =IFERROR(M10/J10,0) -> 5.3244179 | O10: =IFERROR((N10*I10)/23,"") -> 1.7761657 | P10: Luis | Q10: Left to pick: 1-17,19,21,24-37,39,41,
A11: 46231 | B11: DVDU1CSB | C11: {=IF(B11="","",_xlfn._xlws.FILTER('Source List'!I$2:I$268,'Source List'!G$2:G$268='Row Counts'!B11," "))} -> 726 | D11: {=IF(B11="","",_xlfn._xlws.FILTER('Source List'!J$2:J$268,'Source List'!G$2:G$268='Row Counts'!B11," "))} -> 32514 | E11: =IFERROR(Table1[[#This Row],[TOTAL VINES]]-Table1[[#This Row],[VINES LEFT]],"") -> 27282 | F11: 5232 | G11: =IFERROR(D11/C11,0) -> 44.785124 | H11: =IFERROR(E11/C11,0) -> 37.578512 | I11: =Table1[[#This Row],[TOTAL ACRES]]-Table1[[#This Row],[ACRES PICKED]] -> 7.2066116 | J11: =I8-Table1[[#This Row],[ACRES LEFT]] -> 19.641873 | K11: 7 | L11: Gallo | M11: 156.16 | N11: =IFERROR(M11/J11,0) -> 7.9503619 | O11: =IFERROR((N11*I11)/23,"") -> 2.4910943 | P11: Luis | Q11: Left to pick: 36,38,40,68,70-74,76-77,79-81, row 36 is 1/2 picked, row 76 is 1/2 picked
A12: 46231 | B12: DVMA02PG | C12: {=IF(B12="","",_xlfn._xlws.FILTER('Source List'!I$2:I$268,'Source List'!G$2:G$268='Row Counts'!B12," "))} -> 908 | D12: {=IF(B12="","",_xlfn._xlws.FILTER('Source List'!J$2:J$268,'Source List'!G$2:G$268='Row Counts'!B12," "))} -> 94178 | E12: 24105 | F12: =Table1[[#This Row],[TOTAL VINES]]-Table1[[#This Row],[VINES PICKED]] -> 70073 | G12: =IFERROR(D12/C12,0) -> 103.72026 | H12: =IFERROR(E12/C12,0) -> 26.547357 | I12: =Table1[[#This Row],[TOTAL ACRES]]-Table1[[#This Row],[ACRES PICKED]] -> 77.172907 | J12: =Table1[[#This Row],[ACRES PICKED]] -> 26.547357 | K12: 6 | L12: LTW | M12: 142.24 | N12: =IFERROR(M12/J12,0) -> 5.3579722 | O12: =IFERROR((N12*I12)/23,"") -> 17.977839 | P12: Mat | Q12: picked: 215-295,298(1/2W),299-323,344,346-365,367,374-378,381,383,385,387
A13: 46231 | B13: MUMU02PG | C13: {=IF(B13="","",_xlfn._xlws.FILTER('Source List'!I$2:I$268,'Source List'!G$2:G$268='Row Counts'!B13," "))} -> 681 | D13: {=IF(B13="","",_xlfn._xlws.FILTER('Source List'!J$2:J$268,'Source List'!G$2:G$268='Row Counts'!B13," "))} -> 14141 | E13: =IFERROR(Table1[[#This Row],[TOTAL VINES]]-Table1[[#This Row],[VINES LEFT]],"") -> 14141 | F13: 0 | G13: =IFERROR(D13/C13,0) -> 20.765051 | H13: =IFERROR(E13/C13,0) -> 20.765051 | I13: =Table1[[#This Row],[TOTAL ACRES]]-Table1[[#This Row],[ACRES PICKED]] -> 0 | J13: =I10 -> 7.6725404 | K13: 1.75 | L13: Fetzer | M13: 39.56 | N13: =IFERROR(M13/J13,0) -> 5.1560498 | O13: =IFERROR((N13*I13)/23,"") -> 0 | P13: Luis | Q13: FC
A14: 46232 | B14: DVDU1CSB | C14: {=IF(B14="","",_xlfn._xlws.FILTER('Source List'!I$2:I$268,'Source List'!G$2:G$268='Row Counts'!B14," "))} -> 726 | D14: {=IF(B14="","",_xlfn._xlws.FILTER('Source List'!J$2:J$268,'Source List'!G$2:G$268='Row Counts'!B14," "))} -> 32514 | E14: =IFERROR(Table1[[#This Row],[TOTAL VINES]]-Table1[[#This Row],[VINES LEFT]],"") -> 32514 | F14: 0 | G14: =IFERROR(D14/C14,0) -> 44.785124 | H14: =IFERROR(E14/C14,0) -> 44.785124 | I14: =Table1[[#This Row],[TOTAL ACRES]]-Table1[[#This Row],[ACRES PICKED]] -> 0 | J14: =I11 -> 7.2066116 | K14: 2.25 | L14: Gallo | M14: 51.08 | N14: =IFERROR(M14/J14,0) -> 7.0879358 | O14: =IFERROR((N14*I14)/23,"") -> 0 | P14: Luis | Q14: FC
A15: 46232 | B15: DVDU02SB | C15: {=IF(B15="","",_xlfn._xlws.FILTER('Source List'!I$2:I$268,'Source List'!G$2:G$268='Row Counts'!B15," "))} -> 726 | D15: {=IF(B15="","",_xlfn._xlws.FILTER('Source List'!J$2:J$268,'Source List'!G$2:G$268='Row Counts'!B15," "))} -> 28200 | E15: =IFERROR(Table1[[#This Row],[TOTAL VINES]]-Table1[[#This Row],[VINES LEFT]],"") -> 9610 | F15: 18590 | G15: =IFERROR(D15/C15,0) -> 38.842975 | H15: =IFERROR(E15/C15,0) -> 13.236915 | I15: =Table1[[#This Row],[TOTAL ACRES]]-Table1[[#This Row],[ACRES PICKED]] -> 25.606061 | J15: =Table1[[#This Row],[ACRES PICKED]] -> 13.236915 | K15: 5.75 | L15: Gallo | M15: 131.02 | N15: =IFERROR(M15/J15,0) -> 9.898077 | O15: =IFERROR((N15*I15)/23,"") -> 11.019598 | P15: Luis | Q15: Left to pick: 1-30,31,33,40,42-47,49,52,59-67,70, | R15: 2.25 loads other 3 gondolas came out of Block 2 to fill load 3
A16: 46232 | B16: JONR02SB | C16: {=IF(B16="","",_xlfn._xlws.FILTER('Source List'!I$2:I$268,'Source List'!G$2:G$268='Row Counts'!B16," "))} -> 726 | D16: {=IF(B16="","",_xlfn._xlws.FILTER('Source List'!J$2:J$268,'Source List'!G$2:G$268='Row Counts'!B16," "))} -> 4941 | E16: =IFERROR(Table1[[#This Row],[TOTAL VINES]]-Table1[[#This Row],[VINES LEFT]],"") -> 4941 | F16: 0 | G16: =IFERROR(D16/C16,0) -> 6.8057851 | H16: =IFERROR(E16/C16,0) -> 6.8057851 | I16: =Table1[[#This Row],[TOTAL ACRES]]-Table1[[#This Row],[ACRES PICKED]] -> 0 | J16: =Table1[[#This Row],[ACRES PICKED]] -> 6.8057851 | K16: 2.5 | L16: Delicato | M16: 55.8 | N16: =IFERROR(M16/J16,0) -> 8.1989071 | O16: =IFERROR((N16*I16)/23,"") -> 0 | P16: Luis | Q16: FC
A17: 46233 | B17: DVDU02SB | C17: {=IF(B17="","",_xlfn._xlws.FILTER('Source List'!I$2:I$268,'Source List'!G$2:G$268='Row Counts'!B17," "))} -> 726 | D17: {=IF(B17="","",_xlfn._xlws.FILTER('Source List'!J$2:J$268,'Source List'!G$2:G$268='Row Counts'!B17," "))} -> 28200 | E17: =IFERROR(Table1[[#This Row],[TOTAL VINES]]-Table1[[#This Row],[VINES LEFT]],"") -> 27120 | F17: 1080 | G17: =IFERROR(D17/C17,0) -> 38.842975 | H17: =IFERROR(E17/C17,0) -> 37.355372 | I17: =Table1[[#This Row],[TOTAL ACRES]]-Table1[[#This Row],[ACRES PICKED]] -> 1.4876033 | J17: =I15-Table1[[#This Row],[ACRES LEFT]] -> 24.118457 | K17: 9 | L17: Gallo | M17: 210.79 | N17: =IFERROR(M17/J17,0) -> 8.7397796 | O17: =IFERROR((N17*I17)/23,"") -> 0.565275 | P17: Luis | Q17: Left to pick: 8,12,17,19 rows 12 and 19 halfway picked
A18: 46233 | B18: MUMU01SB | C18: {=IF(B18="","",_xlfn._xlws.FILTER('Source List'!I$2:I$268,'Source List'!G$2:G$268='Row Counts'!B18," "))} -> 605 | D18: {=IF(B18="","",_xlfn._xlws.FILTER('Source List'!J$2:J$268,'Source List'!G$2:G$268='Row Counts'!B18," "))} -> 12811 | E18: =IFERROR(Table1[[#This Row],[TOTAL VINES]]-Table1[[#This Row],[VINES LEFT]],"") -> 9035 | F18: 3776 | G18: =IFERROR(D18/C18,0) -> 21.175207 | H18: =IFERROR(E18/C18,0) -> 14.933884 | I18: =Table1[[#This Row],[TOTAL ACRES]]-Table1[[#This Row],[ACRES PICKED]] -> 6.2413223 | J18: =Table1[[#This Row],[ACRES PICKED]] -> 14.933884 | K18: 4 | L18: Fetzer | M18: 91.73 | N18: =IFERROR(M18/J18,0) -> 6.1424073 | O18: =IFERROR((N18*I18)/23,"") -> 1.6668149 | P18: Luis | Q18: Left to pick: 61,63,65-71,73-92, row 71 is 1/2 picked row 61 is 1/2 picked
A19: 46233 | B19: LFEX03VI | C19: {=IF(B19="","",_xlfn._xlws.FILTER('Source List'!I$2:I$268,'Source List'!G$2:G$268='Row Counts'!B19," "))} -> 605 | D19: {=IF(B19="","",_xlfn._xlws.FILTER('Source List'!J$2:J$268,'Source List'!G$2:G$268='Row Counts'!B19," "))} -> 9777 | E19: =IFERROR(Table1[[#This Row],[TOTAL VINES]]-Table1[[#This Row],[VINES LEFT]],"") -> 6926 | F19: =552+881+1418 -> 2851 | G19: =IFERROR(D19/C19,0) -> 16.160331 | H19: =IFERROR(E19/C19,0) -> 11.447934 | I19: =Table1[[#This Row],[TOTAL ACRES]]-Table1[[#This Row],[ACRES PICKED]] -> 4.7123967 | J19: =Table1[[#This Row],[ACRES PICKED]] -> 11.447934 | K19: 2.25 | L19: LTW-Pine | M19: 55.51 | N19: =IFERROR(M19/J19,0) -> 4.8489099 | O19: =IFERROR((N19*I19)/23,"") -> 0.9934777 | P19: Luis | Q19: Left to pick: 91-94,115-138, rows 115-138 only picked on the West side
A20: 46233 | B20: LFEX04VI | C20: {=IF(B20="","",_xlfn._xlws.FILTER('Source List'!I$2:I$268,'Source List'!G$2:G$268='Row Counts'!B20," "))} -> 778 | D20: {=IF(B20="","",_xlfn._xlws.FILTER('Source List'!J$2:J$268,'Source List'!G$2:G$268='Row Counts'!B20," "))} -> 9125 | E20: =IFERROR(Table1[[#This Row],[TOTAL VINES]]-Table1[[#This Row],[VINES LEFT]],"") -> 8663 | F20: 462 | G20: =IFERROR(D20/C20,0) -> 11.728792 | H20: =IFERROR(E20/C20,0) -> 11.134961 | I20: =Table1[[#This Row],[TOTAL ACRES]]-Table1[[#This Row],[ACRES PICKED]] -> 0.59383033 | J20: =Table1[[#This Row],[ACRES PICKED]] -> 11.134961 | K20: 1.75 | L20: LTW-Pine | M20: 45.86 | N20: =IFERROR(M20/J20,0) -> 4.1185594 | O20: =IFERROR((N20*I20)/23,"") -> 0.10633589 | P20: Luis | Q20: Left to pick: 1,52-53,
A21: 46234 | B21: DVDU02SB | C21: {=IF(B21="","",_xlfn._xlws.FILTER('Source List'!I$2:I$268,'Source List'!G$2:G$268='Row Counts'!B21," "))} -> 726 | D21: {=IF(B21="","",_xlfn._xlws.FILTER('Source List'!J$2:J$268,'Source List'!G$2:G$268='Row Counts'!B21," "))} -> 28200 | E21: =IFERROR(Table1[[#This Row],[TOTAL VINES]]-Table1[[#This Row],[VINES LEFT]],"") -> 28200 | F21: 0 | G21: =IFERROR(D21/C21,0) -> 38.842975 | H21: =IFERROR(E21/C21,0) -> 38.842975 | I21: =Table1[[#This Row],[TOTAL ACRES]]-Table1[[#This Row],[ACRES PICKED]] -> 0 | J21: =I17 -> 1.4876033 | K21: 0.5 | L21: Gallo | M21: 11.15 | N21: =IFERROR(M21/J21,0) -> 7.4952778 | O21: =IFERROR((N21*I21)/23,"") -> 0 | P21: Mat | Q21: FC
A22: 46234 | B22: WHWH01GE | C22: {=IF(B22="","",_xlfn._xlws.FILTER('Source List'!I$2:I$268,'Source List'!G$2:G$268='Row Counts'!B22," "))} -> 691 | D22: {=IF(B22="","",_xlfn._xlws.FILTER('Source List'!J$2:J$268,'Source List'!G$2:G$268='Row Counts'!B22," "))} -> 26251 | E22: 14439 | F22: =Table1[[#This Row],[TOTAL VINES]]-Table1[[#This Row],[VINES PICKED]] -> 11812 | G22: =IFERROR(D22/C22,0) -> 37.98987 | H22: =IFERROR(E22/C22,0) -> 20.895803 | I22: =Table1[[#This Row],[TOTAL ACRES]]-Table1[[#This Row],[ACRES PICKED]] -> 17.094067 | J22: =Table1[[#This Row],[ACRES PICKED]] -> 20.895803 | K22: 6.5 | L22: LTW | M22: 152.71 | N22: =IFERROR(M22/J22,0) -> 7.3081661 | O22: =IFERROR((N22*I22)/23,"") -> 5.4315773 | P22: Mat | Q22: Picked 1-79
A23: 46234 | B23: LFEX03VI | C23: {=IF(B23="","",_xlfn._xlws.FILTER('Source List'!I$2:I$268,'Source List'!G$2:G$268='Row Counts'!B23," "))} -> 605 | D23: {=IF(B23="","",_xlfn._xlws.FILTER('Source List'!J$2:J$268,'Source List'!G$2:G$268='Row Counts'!B23," "))} -> 9777 | E23: =IFERROR(Table1[[#This Row],[TOTAL VINES]]-Table1[[#This Row],[VINES LEFT]],"") -> 9777 | F23: 0 | G23: =IFERROR(D23/C23,0) -> 16.160331 | H23: =IFERROR(E23/C23,0) -> 16.160331 | I23: =Table1[[#This Row],[TOTAL ACRES]]-Table1[[#This Row],[ACRES PICKED]] -> 0 | J23: =I19 -> 4.7123967 | L23: LTW-Pine | M23: 12.69 | N23: =IFERROR(M23/J23,0) -> 2.6928972 | O23: =IFERROR((N23*I23)/23,"") -> 0 | P23: Luis | Q23: FC
A24: 46234 | B24: LFEX04VI | C24: {=IF(B24="","",_xlfn._xlws.FILTER('Source List'!I$2:I$268,'Source List'!G$2:G$268='Row Counts'!B24," "))} -> 778 | D24: {=IF(B24="","",_xlfn._xlws.FILTER('Source List'!J$2:J$268,'Source List'!G$2:G$268='Row Counts'!B24," "))} -> 9125 | E24: =IFERROR(Table1[[#This Row],[TOTAL VINES]]-Table1[[#This Row],[VINES LEFT]],"") -> 9125 | F24: 0 | G24: =IFERROR(D24/C24,0) -> 11.728792 | H24: =IFERROR(E24/C24,0) -> 11.728792 | I24: =Table1[[#This Row],[TOTAL ACRES]]-Table1[[#This Row],[ACRES PICKED]] -> 0 | J24: =I20 -> 0.59383033 | L24: LTW-Pine | M24: 4.23 | N24: =IFERROR(M24/J24,0) -> 7.1232468 | O24: =IFERROR((N24*I24)/23,"") -> 0 | P24: Luis | Q24: FC
A25: 46234 | B25: SLHM04SB | C25: {=IF(B25="","",_xlfn._xlws.FILTER('Source List'!I$2:I$268,'Source List'!G$2:G$268='Row Counts'!B25," "))} -> 622 | D25: {=IF(B25="","",_xlfn._xlws.FILTER('Source List'!J$2:J$268,'Source List'!G$2:G$268='Row Counts'!B25," "))} -> 21904 | E25: =IFERROR(Table1[[#This Row],[TOTAL VINES]]-Table1[[#This Row],[VINES LEFT]],"") -> 14787 | F25: =5467+1650 -> 7117 | G25: =IFERROR(D25/C25,0) -> 35.215434 | H25: =IFERROR(E25/C25,0) -> 23.773312 | I25: =Table1[[#This Row],[TOTAL ACRES]]-Table1[[#This Row],[ACRES PICKED]] -> 11.442122 | J25: =Table1[[#This Row],[ACRES PICKED]] -> 23.773312 | K25: 6 | L25: LTW | M25: 140.55 | N25: =IFERROR(M25/J25,0) -> 5.9120917 | O25: =IFERROR((N25*I25)/23,"") -> 2.9411685 | P25: Luis | Q25: East left to pick: 43-45,48-55,58-78,West left to pick: 41-72,83
A26: 46234 | B26: MUMU01SB | C26: {=IF(B26="","",_xlfn._xlws.FILTER('Source List'!I$2:I$268,'Source List'!G$2:G$268='Row Counts'!B26," "))} -> 605 | D26: {=IF(B26="","",_xlfn._xlws.FILTER('Source List'!J$2:J$268,'Source List'!G$2:G$268='Row Counts'!B26," "))} -> 12811 | E26: =IFERROR(Table1[[#This Row],[TOTAL VINES]]-Table1[[#This Row],[VINES LEFT]],"") -> 12811 | F26: 0 | G26: =IFERROR(D26/C26,0) -> 21.175207 | H26: =IFERROR(E26/C26,0) -> 21.175207 | I26: =Table1[[#This Row],[TOTAL ACRES]]-Table1[[#This Row],[ACRES PICKED]] -> 0 | J26: =I18 -> 6.2413223 | K26: 1.75 | L26: Fetzer | M26: 34.51 | N26: =IFERROR(M26/J26,0) -> 5.529277 | O26: =IFERROR((N26*I26)/23,"") -> 0 | P26: Luis | Q26: FC
A27: 46234 | B27: LFDA02PG | C27: {=IF(B27="","",_xlfn._xlws.FILTER('Source List'!I$2:I$268,'Source List'!G$2:G$268='Row Counts'!B27," "))} -> 908 | D27: {=IF(B27="","",_xlfn._xlws.FILTER('Source List'!J$2:J$268,'Source List'!G$2:G$268='Row Counts'!B27," "))} -> 8809 | E27: =IFERROR(Table1[[#This Row],[TOTAL VINES]]-Table1[[#This Row],[VINES LEFT]],"") -> 8809 | F27: 0 | G27: =IFERROR(D27/C27,0) -> 9.7015419 | H27: =IFERROR(E27/C27,0) -> 9.7015419 | I27: =Table1[[#This Row],[TOTAL ACRES]]-Table1[[#This Row],[ACRES PICKED]] -> 0 | J27: =Table1[[#This Row],[ACRES PICKED]] -> 9.7015419 | K27: 2.25 | L27: LTW | M27: 51.04 | N27: =IFERROR(M27/J27,0) -> 5.2610194 | O27: =IFERROR((N27*I27)/23,"") -> 0 | P27: Luis | Q27: FC
A28: 46237 | B28: DVMA02PG | C28: {=IF(B28="","",_xlfn._xlws.FILTER('Source List'!I$2:I$268,'Source List'!G$2:G$268='Row Counts'!B28," "))} -> 908 | D28: {=IF(B28="","",_xlfn._xlws.FILTER('Source List'!J$2:J$268,'Source List'!G$2:G$268='Row Counts'!B28," "))} -> 94178 | E28: =IFERROR(Table1[[#This Row],[TOTAL VINES]]-Table1[[#This Row],[VINES LEFT]],"") -> 50507 | F28: 43671 | G28: =IFERROR(D28/C28,0) -> 103.72026 | H28: =IFERROR(E28/C28,0) -> 55.624449 | I28: =Table1[[#This Row],[TOTAL ACRES]]-Table1[[#This Row],[ACRES PICKED]] -> 48.095815 | J28: =I12-Table1[[#This Row],[ACRES LEFT]] -> 29.077093 | K28: 7 | L28: Delicato | M28: 167.38 | N28: =IFERROR(M28/J28,0) -> 5.7564215 | O28: =IFERROR((N28*I28)/23,"") -> 12.037382 | P28: Leonardo | Q28: left to pick: 42,44-170,172,386,388,390-466,468,470 | R28: May have some half rows that are actually picked in there
A29: 46237 | B29: SLHM04SB | C29: {=IF(B29="","",_xlfn._xlws.FILTER('Source List'!I$2:I$268,'Source List'!G$2:G$268='Row Counts'!B29," "))} -> 622 | D29: {=IF(B29="","",_xlfn._xlws.FILTER('Source List'!J$2:J$268,'Source List'!G$2:G$268='Row Counts'!B29," "))} -> 21904 | E29: =IFERROR(Table1[[#This Row],[TOTAL VINES]]-Table1[[#This Row],[VINES LEFT]],"") -> 21904 | F29: 0 | G29: =IFERROR(D29/C29,0) -> 35.215434 | H29: =IFERROR(E29/C29,0) -> 35.215434 | I29: =Table1[[#This Row],[TOTAL ACRES]]-Table1[[#This Row],[ACRES PICKED]] -> 0 | J29: =I25 -> 11.442122 | K29: 2.75 | L29: LTW | M29: 65.29 | N29: =IFERROR(M29/J29,0) -> 5.7061093 | O29: =IFERROR((N29*I29)/23,"") -> 0 | P29: Mat | Q29: FC
A30: 46237 | B30: SLHM02VI | C30: {=IF(B30="","",_xlfn._xlws.FILTER('Source List'!I$2:I$268,'Source List'!G$2:G$268='Row Counts'!B30," "))} -> 605 | D30: {=IF(B30="","",_xlfn._xlws.FILTER('Source List'!J$2:J$268,'Source List'!G$2:G$268='Row Counts'!B30," "))} -> 11526 | E30: =IFERROR(Table1[[#This Row],[TOTAL VINES]]-Table1[[#This Row],[VINES LEFT]],"") -> 11526 | F30: 0 | G30: =IFERROR(D30/C30,0) -> 19.05124 | H30: =IFERROR(E30/C30,0) -> 19.05124 | I30: =Table1[[#This Row],[TOTAL ACRES]]-Table1[[#This Row],[ACRES PICKED]] -> 0 | J30: =Table1[[#This Row],[ACRES PICKED]] -> 19.05124 | K30: 4 | L30: LTW | M30: 93.64 | N30: =IFERROR(M30/J30,0) -> 4.9151657 | O30: =IFERROR((N30*I30)/23,"") -> 0 | P30: Mat | Q30: FC
A31: 46237 | B31: MFRN03PG | C31: {=IF(B31="","",_xlfn._xlws.FILTER('Source List'!I$2:I$268,'Source List'!G$2:G$268='Row Counts'!B31," "))} -> 807 | D31: {=IF(B31="","",_xlfn._xlws.FILTER('Source List'!J$2:J$268,'Source List'!G$2:G$268='Row Counts'!B31," "))} -> 36108 | E31: =IFERROR(Table1[[#This Row],[TOTAL VINES]]-Table1[[#This Row],[VINES LEFT]],"") -> 14077 | F31: 22031 | G31: =IFERROR(D31/C31,0) -> 44.743494 | H31: =IFERROR(E31/C31,0) -> 17.443618 | I31: =Table1[[#This Row],[TOTAL ACRES]]-Table1[[#This Row],[ACRES PICKED]] -> 27.299876 | J31: =Table1[[#This Row],[ACRES PICKED]] -> 17.443618 | K31: 6 | L31: Gallo | M31: 143.86 | N31: =IFERROR(M31/J31,0) -> 8.2471421 | O31: =IFERROR((N31*I31)/23,"") -> 9.7889547 | P31: Luis | Q31: Left to pick: 32,34-124,126,147-148,150, rows 35,147 half picked
A32: 46238 | B32: DVMA01PN | C32: {=IF(B32="","",_xlfn._xlws.FILTER('Source List'!I$2:I$268,'Source List'!G$2:G$268='Row Counts'!B32," "))} -> 691 | D32: {=IF(B32="","",_xlfn._xlws.FILTER('Source List'!J$2:J$268,'Source List'!G$2:G$268='Row Counts'!B32," "))} -> 30586 | E32: 5676 | F32: =Table1[[#This Row],[TOTAL VINES]]-E32 -> 24910 | G32: =IFERROR(D32/C32,0) -> 44.263386 | H32: =IFERROR(E32/C32,0) -> 8.2141823 | I32: =Table1[[#This Row],[TOTAL ACRES]]-Table1[[#This Row],[ACRES PICKED]] -> 36.049204 | J32: =Table1[[#This Row],[ACRES PICKED]] -> 8.2141823 | K32: 3 | L32: LTW | M32: 70.09 | N32: =IFERROR(M32/J32,0) -> 8.532803 | O32: =IFERROR((N32*I32)/23,"") -> 13.373946 | P32: Luis | Q32: EAST left to pick 55-50,48,36,34-33,31-30,28,5,1, Row 30 is 3/4 picked
A33: 46238 | B33: DVMA02PG | C33: {=IF(B33="","",_xlfn._xlws.FILTER('Source List'!I$2:I$268,'Source List'!G$2:G$268='Row Counts'!B33," "))} -> 908 | D33: {=IF(B33="","",_xlfn._xlws.FILTER('Source List'!J$2:J$268,'Source List'!G$2:G$268='Row Counts'!B33," "))} -> 94178 | E33: =IFERROR(Table1[[#This Row],[TOTAL VINES]]-Table1[[#This Row],[VINES LEFT]],"") -> 63517 | F33: 30661 | G33: =IFERROR(D33/C33,0) -> 103.72026 | H33: =IFERROR(E33/C33,0) -> 69.952643 | I33: =Table1[[#This Row],[TOTAL ACRES]]-Table1[[#This Row],[ACRES PICKED]] -> 33.767621 | J33: =I28-Table1[[#This Row],[ACRES LEFT]] -> 14.328194 | K33: 4 | L33: Delicato | M33: 93.58 | N33: =IFERROR(M33/J33,0) -> 6.5311791 | O33: =IFERROR((N33*I33)/23,"") -> 9.5887992 | P33: Leonardo | Q33: Left to pick: 60,62,64,65(1/2),66-146,148,386,388,390-448,450
A34: 46238 | B34: PRHZ02PN | C34: {=IF(B34="","",_xlfn._xlws.FILTER('Source List'!I$2:I$268,'Source List'!G$2:G$268='Row Counts'!B34," "))} -> 691 | D34: {=IF(B34="","",_xlfn._xlws.FILTER('Source List'!J$2:J$268,'Source List'!G$2:G$268='Row Counts'!B34," "))} -> 4869 | E34: =IFERROR(Table1[[#This Row],[TOTAL VINES]]-Table1[[#This Row],[VINES LEFT]],"") -> 4869 | F34: 0 | G34: =IFERROR(D34/C34,0) -> 7.0463097 | H34: =IFERROR(E34/C34,0) -> 7.0463097 | I34: =Table1[[#This Row],[TOTAL ACRES]]-Table1[[#This Row],[ACRES PICKED]] -> 0 | J34: =Table1[[#This Row],[ACRES PICKED]] -> 7.0463097 | K34: 1 | L34: LTW-KOSHER | M34: 37.35 | N34: =IFERROR(M34/J34,0) -> 5.300647 | O34: =IFERROR((N34*I34)/23,"") -> 0 | P34: Mat | Q34: FC - 1 hand pick load and 2.5 gondolas
A35: 46238 | B35: PRHZ03PN | C35: {=IF(B35="","",_xlfn._xlws.FILTER('Source List'!I$2:I$268,'Source List'!G$2:G$268='Row Counts'!B35," "))} -> 691 | D35: {=IF(B35="","",_xlfn._xlws.FILTER('Source List'!J$2:J$268,'Source List'!G$2:G$268='Row Counts'!B35," "))} -> 4876 | E35: =IFERROR(Table1[[#This Row],[TOTAL VINES]]-Table1[[#This Row],[VINES LEFT]],"") -> 2476 | F35: 2400 | G35: =IFERROR(D35/C35,0) -> 7.0564399 | H35: =IFERROR(E35/C35,0) -> 3.5832127 | I35: =Table1[[#This Row],[TOTAL ACRES]]-Table1[[#This Row],[ACRES PICKED]] -> 3.4732272 | J35: =Table1[[#This Row],[ACRES PICKED]] -> 3.5832127 | K35: 1.5 | L35: LTW-KOSHER | M35: 16.27 | N35: =IFERROR(M35/J35,0) -> 4.5406179 | O35: =IFERROR((N35*I35)/23,"") -> 0.68567816 | P35: Mat | Q35: Left to pick: 76-105 3.25 gondolas | 1 hand load and 1.5 machine loads
A36: 46238 | B36: WHWH01GE | C36: {=IF(B36="","",_xlfn._xlws.FILTER('Source List'!I$2:I$268,'Source List'!G$2:G$268='Row Counts'!B36," "))} -> 691 | D36: {=IF(B36="","",_xlfn._xlws.FILTER('Source List'!J$2:J$268,'Source List'!G$2:G$268='Row Counts'!B36," "))} -> 26251 | E36: =IFERROR(Table1[[#This Row],[TOTAL VINES]]-Table1[[#This Row],[VINES LEFT]],"") -> 26251 | F36: 0 | G36: =IFERROR(D36/C36,0) -> 37.98987 | H36: =IFERROR(E36/C36,0) -> 37.98987 | I36: =Table1[[#This Row],[TOTAL ACRES]]-Table1[[#This Row],[ACRES PICKED]] -> 0 | J36: =I22 -> 17.094067 | K36: 3.25 | L36: TWG-WDBG | M36: 77.77 | N36: =IFERROR(M36/J36,0) -> 4.5495318 | O36: =IFERROR((N36*I36)/23,"") -> 0 | P36: Luis | Q36: FC
A37: 46238 | B37: LFBT02SB | C37: {=IF(B37="","",_xlfn._xlws.FILTER('Source List'!I$2:I$268,'Source List'!G$2:G$268='Row Counts'!B37," "))} -> 726 | D37: {=IF(B37="","",_xlfn._xlws.FILTER('Source List'!J$2:J$268,'Source List'!G$2:G$268='Row Counts'!B37," "))} -> 27203 | E37: =Table1[[#This Row],[TOTAL VINES]]-Table1[[#This Row],[VINES LEFT]] -> 20338 | F37: 6865 | G37: =IFERROR(D37/C37,0) -> 37.469697 | H37: =IFERROR(E37/C37,0) -> 28.013774 | I37: =Table1[[#This Row],[TOTAL ACRES]]-Table1[[#This Row],[ACRES PICKED]] -> 9.4559229 | J37: =Table1[[#This Row],[ACRES PICKED]] -> 28.013774 | K37: 8 | L37: LTW | M37: 191.92 | N37: 3 | O37: =IFERROR((N37*I37)/23,"") -> 1.2333812 | P37: Kyle | Q37: left to pick: 66(1/2 east), 70-74, 91, 93, 94(1/2 W), 95-99, 114, 118-159
A38: 46238 | B38: MFRN03PG | C38: {=IF(B38="","",_xlfn._xlws.FILTER('Source List'!I$2:I$268,'Source List'!G$2:G$268='Row Counts'!B38," "))} -> 807 | D38: {=IF(B38="","",_xlfn._xlws.FILTER('Source List'!J$2:J$268,'Source List'!G$2:G$268='Row Counts'!B38," "))} -> 36108 | E38: =IFERROR(Table1[[#This Row],[TOTAL VINES]]-Table1[[#This Row],[VINES LEFT]],"") -> 30971 | F38: 5137 | G38: =IFERROR(D38/C38,0) -> 44.743494 | H38: =IFERROR(E38/C38,0) -> 38.377943 | I38: =Table1[[#This Row],[TOTAL ACRES]]-Table1[[#This Row],[ACRES PICKED]] -> 6.3655514 | J38: =I31-Table1[[#This Row],[ACRES LEFT]] -> 20.934325 | K38: 7 | L38: Gallo | M38: 167.74 | N38: =IFERROR(M38/J38,0) -> 8.0126779 | O38: =IFERROR((N38*I38)/23,"") -> 2.2176136 | P38: Abel | Q38: left to pick: 65,67,68(1/2),69-86,89,91(1/2)
A39: 46239 | B39: DVMA02PG | C39: {=IF(B39="","",_xlfn._xlws.FILTER('Source List'!I$2:I$268,'Source List'!G$2:G$268='Row Counts'!B39," "))} -> 908 | D39: {=IF(B39="","",_xlfn._xlws.FILTER('Source List'!J$2:J$268,'Source List'!G$2:G$268='Row Counts'!B39," "))} -> 94178 | E39: =IFERROR(Table1[[#This Row],[TOTAL VINES]]-Table1[[#This Row],[VINES LEFT]],"") -> 87308 | F39: 6870 | G39: =IFERROR(D39/C39,0) -> 103.72026 | H39: =IFERROR(E39/C39,0) -> 96.154185 | I39: =Table1[[#This Row],[TOTAL ACRES]]-Table1[[#This Row],[ACRES PICKED]] -> 7.5660793 | J39: =I33-Table1[[#This Row],[ACRES LEFT]] -> 26.201542 | K39: 7 | L39: Delicato | M39: 163.02 | N39: =IFERROR(M39/J39,0) -> 6.2217713 | O39: =IFERROR((N39*I39)/23,"") -> 2.0467137 | P39: Luis | Q39: Left to pick: 102-107,109,111,386,388,390-413,415, row 102 (54 unpicked) row 412 (51 unpicked)
A40: 46239 | B40: MFRN03PG | C40: {=IF(B40="","",_xlfn._xlws.FILTER('Source List'!I$2:I$268,'Source List'!G$2:G$268='Row Counts'!B40," "))} -> 807 | D40: {=IF(B40="","",_xlfn._xlws.FILTER('Source List'!J$2:J$268,'Source List'!G$2:G$268='Row Counts'!B40," "))} -> 36108 | E40: =IFERROR(Table1[[#This Row],[TOTAL VINES]]-Table1[[#This Row],[VINES LEFT]],"") -> 36108 | F40: 0 | G40: =IFERROR(D40/C40,0) -> 44.743494 | H40: =IFERROR(E40/C40,0) -> 44.743494 | I40: =Table1[[#This Row],[TOTAL ACRES]]-Table1[[#This Row],[ACRES PICKED]] -> 0 | J40: =I38 -> 6.3655514 | K40: 2.5 | L40: Gallo | M40: 57.08 | N40: =IFERROR(M40/J40,0) -> 8.9670158 | O40: =IFERROR((N40*I40)/23,"") -> 0 | P40: Luis | Q40: FC
...

Sheet Sheet1
A1: Code | B1: Variety | C1: Block | D1: Acres Remaining | E1: Est. Tons Remaining | F1: Last Brix Reading
A2: CLAT05CS | B2: CS | C2: Clements Atkins B5 CS | D2: 34.92 | E2: 244.44 | F2: 23.5 on 10/20
A3: DBAI04CS | B3: CS | C3: Donald Airport B4 CS | D3: 9.27 | E3: 64.89 | F3: 24.3 on 10/20
A4: LAPR05CS | B4: CS | C4: La Prima B5 CS | D4: 43.1 | E4: =347-72 -> 275 | F4: 23.1 on 10/20
A5: MRPR01CS | B5: CS | C5: MRP B1 CS | D5: 35.04 | E5: 262.8 | F5: 23.1 on 10/20
A6: POCR03CS | B6: CS | C6: Craig Patriot Oaks - Hillltop B3 CS | D6: 59.66 | E6: 447.45 | F6: 24.4 on 10/20

Sheet Stats
B1: Sum of ACRES PICKED SINCE LAST COUNT | C1: Sum of TONS PICKED TODAY
A2: 45876 | B2: 21.975037 | C2: 116.02
A3: 45877 | B3: 19.654276 | C3: 106.16
A4: 45880 | B4: 6.1266031 | C4: 40
A5: 45881 | B5: 33.743986 | C5: 270.08
A6: 45882 | B6: 26.178912 | C6: 277.99
A7: 45883 | B7: 55.477657 | C7: 480.66
A8: 45884 | B8: 40.76 | C8: 394.51
A9: 45887 | B9: 71.277078 | C9: 546.99
A10: 45888 | B10: 61.474286 | C10: 500.599
A11: 45889 | B11: 82.272267 | C11: 630.08
A12: 45890 | B12: 89.203457 | C12: 593.8
A13: 45891 | B13: 33.700749 | C13: 221.03
... A30: 45909 | B30: 90.332003 | C30: 865.97

Sheet Source List
A1: Prince CB | F1: VINEYARD CODE | G1: SUB-BLOCK | H1: REGION | I1: SPACING | J1: TOTAL VINES | K1: ROW COUNT ACRES | L1: NOTES | N1: Updated: | O1: 45503 | P1: 0.5
A2: BLK | B2: AC. | C2: TPA | D2: EST TONS | F2: 98OK01CS | G2: 98OK01CS | H2: CLEMENTS | I2: 726 | J2: 16379 | K2: =J2/I2 -> 22.560606 | N2: By: | O2: Maria Z.
A3: 5 | B3: 0.37 | C3: 2.64 | D3: =B3*C3 -> 0.9768 | F3: 98OK02CS | G3: 98OK02CS | H3: CLEMENTS | I3: 726 | J3: 11178 | K3: =J3/I3 -> 15.396694
A4: 6 | B4: 3.15 | C4: 5.82 | D4: =B4*C4 -> 18.333 | F4: 98OK03MA | G4: 98OK03MA | H4: CLEMENTS | I4: 691 | J4: 13027 | K4: =J4/I4 -> 18.852388
F5: 98OK04CS | G5: 98OK04CS | H5: CLEMENTS | I5: 691 | J5: 18124 | K5: =J5/I5 -> 26.228654
A6: 10 | B6: 4.25 | C6: 2.73 | D6: =B6*C6 -> 11.6025 | F6: 98OK05CS | G6: 98OK05CS | H6: CLEMENTS | I6: 691 | J6: 13746 | K6: =J6/I6 -> 19.892909
F7: 98OK06CS | G7: 98OK06CS | H7: CLEMENTS | I7: 691 | J7: 15567 | K7: =J7/I7 -> 22.52822
A8: 14 | B8: 3.03 | C8: ? | D8: =3.03*8 -> 24.24 | E8: estimated 8tpa | F8: 98OK07ME | G8: 98OK07ME | H8: CLEMENTS | I8: 691 | J8: 25345 | K8: =J8/I8 -> 36.678726
F9: 98OK08PS | G9: 98OK08PS | H9: CLEMENTS | I9: 691 | J9: 16485 | K9: =J9/I9 -> 23.856729
F10: 98OK09CS | G10: 98OK09CS | H10: CLEMENTS | I10: 726 | J10: 27935 | K10: =J10/I10 -> 38.477961
F11: 98OK10ZN | G11: 98OK10ZN | H11: CLEMENTS | I11: 691 | J11: 12621 | K11: =J11/I11 -> 18.264834
F12: 98OK11CF | G12: 98OK11CF | H12: CLEMENTS | I12: 807 | J12: 16549 | K12: =J12/I12 -> 20.506815
F13: ARDA01CS | G13: ARDA01CS | H13: LODI | I13: 622 | J13: =10935+11704 -> 22639 | K13: =J13/I13 -> 36.397106
F14: BAPE01CH | G14: BAPE01CH | H14: LODI | I14: 726 | J14: 30107 | K14: =J14/I14 -> 41.469697
F15: BAVC01ZN | G15: BAVC01ZN | H15: CLEMENTS | I15: 622 | J15: 10298 | K15: =J15/I15 -> 16.55627
F16: BAVC02PR | G16: BAVC02PR | H16: CLEMENTS | I16: 622 | J16: 7170 | K16: =J16/I16 -> 11.527331
F17: BEBU01ME | G17: BEBU01ME | H17: LODI | I17: 807 | J17: 37779 | K17: =J17/I17 -> 46.814126
F18: BHCH01CS | G18: BHCH01CS-1 | H18: CLEMENTS | I18: 622 | J18: 2814 | K18: =J18/I18 -> 4.5241158
F19: BHCH01CS | G19: BHCH01CS-2 | H19: CLEMENTS | I19: 622 | J19: 2398 | K19: =J19/I19 -> 3.8553055
F20: BHCH01CS | G20: BHCH01CS-3 | H20: CLEMENTS | I20: 622 | J20: 751 | K20: =J20/I20 -> 1.2073955
F21: BHCH01CS | G21: BHCH01CS-4 | H21: CLEMENTS | I21: 622 | J21: 2031 | K21: =J21/I21 -> 3.2652733
A22: 15 | B22: 13.09 | C22: 11.52 | D22: =B22*C22 -> 150.7968 | F22: BHCH01CS | G22: BHCH01CS-5 | H22: CLEMENTS | I22: 622 | J22: 1215 | K22: =J22/I22 -> 1.9533762
A23: 16 | B23: 0 | C23: 8.5 | D23: =B23*C23 -> 0 | F23: BHCH01CS | G23: BHCH01CS-6 | H23: CLEMENTS | I23: 622 | J23: 612 | K23: =J23/I23 -> 0.98392283
A24: 17 | B24: 0 | C24: 11.11 | D24: =B24*C24 -> 0 | F24: BHCH01CS | G24: BHCH01CS-7 | H24: CLEMENTS | I24: 622 | J24: 2600 | K24: =J24/I24 -> 4.1800643
D25: =SUM(D3:D24) -> 205.9491 | F25: BHCH01CS | G25: BHCH01CS-8 | H25: CLEMENTS | I25: 622 | J25: 1618 | K25: =J25/I25 -> 2.6012862
F26: BHCH01CS | G26: BHCH01CS-9 | H26: CLEMENTS | I26: 622 | J26: 1283 | K26: =J26/I26 -> 2.062701
F27: BHCH01CS | G27: BHCH01CS-10 | H27: CLEMENTS | I27: 622 | J27: 1455 | K27: =J27/I27 -> 2.3392283
F28: BHCH01CS | G28: BHCH01CS-11 | H28: CLEMENTS | I28: 622 | J28: 774 | K28: =J28/I28 -> 1.244373
F29: BHCH01CS | G29: BHCH01CS-12 | H29: CLEMENTS | I29: 622 | J29: 3922 | K29: =J29/I29 -> 6.3054662
F30: BHCH01CS | G30: BHCH01CS-13 | H30: CLEMENTS | I30: 622 | J30: 5743 | K30: =J30/I30 -> 9.233119
F31: BHCH01CS | G31: BHCH01CS-ALL | H31: CLEMENTS | I31: 622 | J31: =SUM(J18:J30) -> 27216 | K31: =J31/I31 -> 43.755627
F32: BSHMOHCS | G32: BSHMOHCS | H32: CLEMENTS | I32: 605 | J32: 2554 | K32: =J32/I32 -> 4.2214876
A33: BHCH01CS | F33: CL3A01PV | G33: CL3A01PV | H33: CLEMENTS | I33: 681 | J33: 60308 | K33: =J33/I33 -> 88.558003
A34: set | B34: vines | F34: CL3A02SB | G34: CL3A02SB | H34: CLEMENTS | I34: 622 | J34: 30664 | K34: =J34/I34 -> 49.299035
A35: 7 | B35: 2600 | F35: CL3A04PV | G35: CL3A04PV | H35: CLEMENTS | I35: 681 | J35: 36152 | K35: =J35/I35 -> 53.086637
A36: 2 | B36: 2398 | C36: all | F36: CL3A05ZN | G36: CL3A05ZN | H36: CLEMENTS | I36: 681 | J36: 28396 | K36: =J36/I36 -> 41.697504
A37: 6 | B37: 612 | C37: fc | F37: CLAT01CS | G37: CLAT01CS | H37: CLEMENTS | I37: 681 | J37: =SUM(J38:J39) -> 26721 | K37: =J37/I37 -> 39.237885
A38: 6 | B38: 612 | C38: fc | F38: CLAT01CS | G38: CLAT01CS-DISCH | H38: CLEMENTS | I38: 681 | J38: 23968 | K38: =J38/I38 -> 35.195301
F39: CLAT01CS | G39: CLAT01CS-NS | H39: CLEMENTS | I39: 681 | J39: 2753 | K39: =J39/I39 -> 4.0425844
F40: CLAT02CH | G40: CLATCH-84ac | H40: CLEMENTS | I40: 681 | J40: 57068 | K40: =J40/I40 -> 83.800294
...
